<?xml version="1.0" ?>
<sdf version="1.5">
  <model name="wind_power_plant">
      <static>false</static>      
      <link name="tower">
	<collision name='collision'>
          <geometry>
	    <mesh><uri>model://wind_power_plant/meshes/tower.dae</uri></mesh>
          </geometry>
	</collision>
  
	<pose>0 0 0  0 0 0</pose>
        <visual name="visual">
          <geometry>
            <mesh><uri>model://wind_power_plant/meshes/tower.dae</uri></mesh>
          </geometry>
        </visual>
      </link>

      <joint name="tower_base" type="fixed">
	<child>tower</child>
	<parent>world</parent>
	<axis>
	  <xyz>0 0 1</xyz>
	</axis>
      </joint> 
      
      <link name="gondola">
	<pose>0 0 3  0 0 0</pose>
	<collision name='collision'>
          <geometry>
            <mesh><uri>model://wind_power_plant/meshes/gondola.dae</uri></mesh>
          </geometry>
	</collision>

        <visual name="visual">
          <geometry>
            <mesh><uri>model://wind_power_plant/meshes/gondola.dae</uri></mesh>
          </geometry>
	  
	    <material>
	      <ambient>1 0 0 1</ambient>
	      <diffuse>0 0 1 1</diffuse>
	      <specular>0.1 0.1 0.1 1</specular>
	      <emissive>0 0 0 0</emissive>
	    </material>

        </visual>

	<inertial>
	  <mass>1.0</mass>
	</inertial>
	
      </link>

      <link name="turbine">
	<pose>0.25 0 3  0 0 0</pose>

	<collision name='collision'>
          <geometry>
	    <mesh><uri>model://wind_power_plant/meshes/turbine.dae</uri></mesh>
          </geometry>
	</collision>

        <visual name="visual">
          <geometry>
            <mesh><uri>model://wind_power_plant/meshes/turbine.dae</uri></mesh>
          </geometry>
        </visual>
      </link>

      <joint type="revolute" name="gondola_hinge">
        <pose>0 0 0 0 0 0</pose>
        <child>gondola</child>
        <parent>tower</parent>
        <axis>
          <xyz>0 0 1</xyz>
	  <dynamics>
	    <friction>1</friction>
	  </dynamics>
        </axis>
      </joint>

      <joint type="revolute" name="turbine_hinge">
        <pose>0 0 0 0 0 0</pose>
        <child>turbine</child>
        <parent>gondola</parent>
        <axis>
          <xyz>1 0 0</xyz>
        </axis>
      </joint>
      
    </model>
</sdf>
